<?xml version="1.0" ?>
<robot xmlns:xacro="mecano" name="wheels">

    <xacro:macro name="wheel_dimension">
        <cylinder radius="0.033" length="0.024" />
    </xacro:macro>

    <xacro:macro name="wheels">
        <link name="left_wheel">
            <visual>
                <xacro:default_origin />
                <geometry>
                    <xacro:wheel_dimension />
                </geometry>
                <material name="black" />
            </visual>
            <collision>
                <xacro:default_origin />
                <geometry>
                    <xacro:wheel_dimension />
                </geometry>
            </collision>
            <inertial>
                <xacro:default_origin />
                <mass value="${wheel_mass}" />
                <inertia ixx="0.000049" ixy="0.0" ixz="0.0" iyy="0.000049" iyz="0.0" izz="0.000049" />
            </inertial>
        </link>

        <joint name="left_wheel_joint" type="continuous">
            <axis xyz="0 0 1" />
            <parent link="base_link" />
            <child link="left_wheel" />
            <origin rpy="-1.5708 0 0" xyz="0.09 0.0715 0.0" />
        </joint>

        <link name="right_wheel">
            <visual>
                <xacro:default_origin />
                <geometry>
                    <xacro:wheel_dimension />
                </geometry>
                <material name="black" />
            </visual>
            <collision>
                <xacro:default_origin />
                <geometry>
                    <xacro:wheel_dimension />
                </geometry>
            </collision>
            <inertial>
                <xacro:default_origin />
                <mass value="${wheel_mass}" />
                <inertia ixx="0.000049" ixy="0.0" ixz="0.0" iyy="0.000049" iyz="0.0" izz="0.000049" />
            </inertial>
        </link>

        <joint name="right_wheel_joint" type="continuous">
            <axis xyz="0 0 1" />
            <parent link="base_link" />
            <child link="right_wheel" />
            <origin rpy="-1.5708 0 0" xyz="0.09 -0.0715 0.0" />
        </joint>
    </xacro:macro>

</robot>
